<?xml version="1.0"?>
<robot 
    xmlns:xacro="http://www.ros.org/wiki/xacro">
    <xacro:macro name="insert_transmission" params="name">
        <transmission name="${name}_tran">
            <type>transmission_interface/SimpleTransmission</type>
            <joint name="${name}">
                <hardwareInterface>hardware_interface/EffortJointInterface</hardwareInterface>
            </joint>
            <actuator name="${name}_motor">
                <hardwareInterface>EffortJointInterface</hardwareInterface>
                <mechanicalReduction>1</mechanicalReduction>
            </actuator>
        </transmission>
    </xacro:macro>
    <xacro:macro name="uthai_left_leg" params="parent">
        <!-- left hip yaw -->
        <joint name="l_hip_yaw_joint" type="revolute">
            <axis xyz="0 0 1" />
            <origin xyz="0.008 0.09 -0.06" rpy="0 0 ${pi/2}"/>
            <parent link="${parent}"/>
            <child link="l_hip_yaw_link"/>
            <limit effort="10" lower="${-pi*0.9}" upper="${pi*0.9}" velocity="5.6548668"/>
            <dynamics damping="0.1" friction="0.0"/>
        </joint>
        <xacro:insert_transmission name="l_hip_yaw_joint"/>
        <link name="l_hip_yaw_link">
            <collision>
                <geometry>
                    <mesh filename="package://uthai_description/meshes/l_hip_yaw.STL"/>
                </geometry>
            </collision>
            <visual>
                <geometry>
                    <mesh filename="package://uthai_description/meshes/l_hip_yaw.STL"/>
                </geometry>
                <material name="grey"/>
            </visual>
            <inertial>
                <origin xyz="0.00000000 0.02500000 -0.00735017"/>
                <mass value="0.090718"/>
                <inertia ixx="0.00014114" ixy="0.00000000" ixz="0.00000000" iyy="0.00002016" iyz="0.00000000" izz="0.00014272" />
            </inertial>
        </link>
        <!-- left hip roll -->
        <joint name="l_hip_roll_joint" type="revolute">
            <axis xyz="0 0 1" />
            <origin xyz="0 0 -0.036" rpy="${pi/2} 0 0"/>
            <parent link="l_hip_yaw_link"/>
            <child link="l_hip_roll_link"/>
            <limit effort="10" lower="${-pi*0.9}" upper="${pi*0.9}" velocity="5.6548668"/>
            <dynamics damping="0.1" friction="0.0"/>
        </joint>
        <xacro:insert_transmission name="l_hip_roll_joint"/>
        <link name="l_hip_roll_link">
            <collision>
                <geometry>
                    <mesh filename="package://uthai_description/meshes/l_hip_roll.STL"/>
                </geometry>
            </collision>
            <visual>
                <geometry>
                    <mesh filename="package://uthai_description/meshes/l_hip_roll.STL"/>
                </geometry>
                <material name="grey"/>
            </visual>
            <inertial>
                <origin xyz="-0.00000789 -0.01513929 -0.02477769"/>
                <mass value="0.34200000"/>
                <inertia ixx="0.00032736" ixy="0.00000086" ixz="-0.00000008" iyy="0.00027354" iyz="0.00000709" izz="0.00014799" />
            </inertial>
        </link>
        <!-- left hip pitch -->
        <joint name="l_hip_pitch_joint" type="revolute">
            <axis xyz="0 0 1" />
            <origin xyz="0 0 -0.004" rpy="${-pi/2} 0 ${-pi/2}"/>
            <parent link="l_hip_roll_link"/>
            <child link="l_hip_pitch_link"/>
            <limit effort="10" lower="${-pi*0.9}" upper="${pi*0.9}" velocity="5.6548668"/>
            <dynamics damping="0.1" friction="0.0"/>
        </joint>
        <xacro:insert_transmission name="l_hip_pitch_joint"/>
        <link name="l_hip_pitch_link">
            <collision>
                <geometry>
                    <mesh filename="package://uthai_description/meshes/l_hip_pitch.STL"/>
                </geometry>
            </collision>
            <visual>
                <geometry>
                    <mesh filename="package://uthai_description/meshes/l_hip_pitch.STL"/>
                </geometry>
                <material name="grey"/>
            </visual>
            <inertial>
                <origin xyz="0.21946422 -0.00013856 0.00003754"/>
                <mass value="0.29655036"/>
                <inertia ixx="0.00010413" ixy="-0.00000267" ixz="0.00000165" iyy="0.00255502" iyz="0.00000000" izz="0.00251726" />
            </inertial>
        </link>
        <!-- left knee pitch -->
        <joint name="l_knee_pitch_joint" type="revolute">
            <axis xyz="0 0 1" />
            <origin xyz="0.3 0 0" rpy="0 0 0"/>
            <parent link="l_hip_pitch_link"/>
            <child link="l_knee_pitch_link"/>
            <limit effort="10" lower="${-pi*0.9}" upper="${pi*0.9}" velocity="5.6548668"/>
            <dynamics damping="0.1" friction="0.0"/>
        </joint>
        <xacro:insert_transmission name="l_knee_pitch_joint"/>
        <link name="l_knee_pitch_link">
            <collision>
                <geometry>
                    <mesh filename="package://uthai_description/meshes/l_knee_pitch.STL"/>
                </geometry>
            </collision>
            <visual>
                <geometry>
                    <mesh filename="package://uthai_description/meshes/l_knee_pitch.STL"/>
                </geometry>
                <material name="grey"/>
            </visual>
            <inertial>
                <origin xyz="0.16353031 0.00000000 0.00013618"/>
                <mass value="0.13584790"/>
                <inertia ixx="0.00005765" ixy="0.00000000" ixz="0.00000009" iyy="0.00126779" iyz="0.00000000" izz="0.00124133" />
            </inertial>
        </link>
        <!-- left ankle pitch -->
        <joint name="l_ankle_pitch_joint" type="revolute">
            <axis xyz="0 0 1" />
            <origin xyz="0.315 0 0" rpy="0 0 0"/>
            <parent link="l_knee_pitch_link"/>
            <child link="l_ankle_pitch_link"/>
            <limit effort="10" lower="${-pi*0.9}" upper="${pi*0.9}" velocity="5.6548668"/>
            <dynamics damping="0.1" friction="0.0"/>
        </joint>
        <xacro:insert_transmission name="l_ankle_pitch_joint"/>
        <link name="l_ankle_pitch_link">
            <collision>
                <geometry>
                    <mesh filename="package://uthai_description/meshes/l_ankle_pitch.STL"/>
                </geometry>
            </collision>
            <visual>
                <geometry>
                    <mesh filename="package://uthai_description/meshes/l_ankle_pitch.STL"/>
                </geometry>
                <material name="grey"/>
            </visual>
            <inertial>
                <origin xyz="-0.01513929 0.02075769 0.00000789"/>
                <mass value="0.34200000"/>
                <inertia ixx="0.00027354" ixy="-0.00000709" ixz="-0.00000086" iyy="0.00014799" iyz="-0.00000008" izz="0.00032736" />
            </inertial>
        </link>
        <!-- left ankle roll -->
        <joint name="l_ankle_roll_joint" type="revolute">
            <axis xyz="0 0 1" />
            <origin xyz="0 0 0" rpy="${pi/2} 0 0"/>
            <parent link="l_ankle_pitch_link"/>
            <child link="l_ankle_roll_link"/>
            <limit effort="10" lower="${-pi*0.9}" upper="${pi*0.9}" velocity="5.6548668"/>
            <dynamics damping="0.1" friction="0.0"/>
        </joint>
        <xacro:insert_transmission name="l_ankle_roll_joint"/>
        <link name="l_ankle_roll_link">
            <collision>
                <geometry>
                    <mesh filename="package://uthai_description/meshes/l_ankle_roll.STL"/>
                </geometry>
            </collision>
            <visual>
                <geometry>
                    <mesh filename="package://uthai_description/meshes/l_ankle_roll.STL"/>
                </geometry>
                <material name="grey"/>
            </visual>
            <inertial>
                <origin xyz="0.03576926 -0.08779574 -0.00045842"/>
                <mass value="0.10500000"/>
                <inertia ixx="0.00123572" ixy="0.00000500" ixz="0.00000812" iyy="0.00031773" iyz="0.00000828" izz="0.00094763" />
            </inertial>
        </link>
    </xacro:macro>
    <xacro:macro name="uthai_right_leg" params="parent">
        <!-- right hip yaw -->
        <joint name="r_hip_yaw_joint" type="revolute">
            <axis xyz="0 0 1" />
            <origin xyz="0.008 -0.09 -0.06" rpy="0 0 ${-pi/2}"/>
            <parent link="${parent}"/>
            <child link="r_hip_yaw_link"/>
            <limit effort="10" lower="${-pi*0.9}" upper="${pi*0.9}" velocity="5.6548668"/>
            <dynamics damping="0.1" friction="0.0"/>
        </joint>
        <xacro:insert_transmission name="r_hip_yaw_joint"/>
        <link name="r_hip_yaw_link">
            <collision>
                <geometry>
                    <mesh filename="package://uthai_description/meshes/r_hip_yaw.STL"/>
                </geometry>
            </collision>
            <visual>
                <geometry>
                    <mesh filename="package://uthai_description/meshes/r_hip_yaw.STL"/>
                </geometry>
                <material name="grey"/>
            </visual>
            <inertial>
                <origin xyz="0.00000000 -0.02500000 -0.00735017"/>
                <mass value="0.090718"/>
                <inertia ixx="0.00014114" ixy="0.00000000" ixz="0.00000000" iyy="0.00002016" iyz="0.00000000" izz="0.00014272" />
            </inertial>
        </link>
        <!-- right hip roll -->
        <joint name="r_hip_roll_joint" type="revolute">
            <axis xyz="0 0 1" />
            <origin xyz="0 0 -0.036" rpy="${pi/2} 0 ${pi}"/>
            <parent link="r_hip_yaw_link"/>
            <child link="r_hip_roll_link"/>
            <limit effort="10" lower="${-pi*0.9}" upper="${pi*0.9}" velocity="5.6548668"/>
            <dynamics damping="0.1" friction="0.0"/>
        </joint>
        <xacro:insert_transmission name="r_hip_roll_joint"/>
        <link name="r_hip_roll_link">
            <collision>
                <geometry>
                    <mesh filename="package://uthai_description/meshes/r_hip_roll.STL"/>
                </geometry>
            </collision>
            <visual>
                <geometry>
                    <mesh filename="package://uthai_description/meshes/r_hip_roll.STL"/>
                </geometry>
                <material name="grey"/>
            </visual>
            <inertial>
                <origin xyz="-0.00000789 -0.01513929 -0.02477769"/>
                <mass value="0.34200000"/>
                <inertia ixx="0.00032736" ixy="0.00000086" ixz="-0.00000008" iyy="0.00027354" iyz="0.00000709" izz="0.00014799" />
            </inertial>
        </link>
        <!-- right hip pitch -->
        <joint name="r_hip_pitch_joint" type="revolute">
            <axis xyz="0 0 1" />
            <origin xyz="0 0 -0.004" rpy="${-pi/2} 0 ${-pi/2}"/>
            <parent link="r_hip_roll_link"/>
            <child link="r_hip_pitch_link"/>
            <limit effort="10" lower="${-pi*0.9}" upper="${pi*0.9}" velocity="5.6548668"/>
            <dynamics damping="0.1" friction="0.0"/>
        </joint>
        <xacro:insert_transmission name="r_hip_pitch_joint"/>
        <link name="r_hip_pitch_link">
            <collision>
                <geometry>
                    <mesh filename="package://uthai_description/meshes/r_hip_pitch.STL"/>
                </geometry>
            </collision>
            <visual>
                <geometry>
                    <mesh filename="package://uthai_description/meshes/r_hip_pitch.STL"/>
                </geometry>
                <material name="grey"/>
            </visual>
            <inertial>
                <origin xyz="0.21946422 -0.00013856 0.00003754"/>
                <mass value="0.29655036"/>
                <inertia ixx="0.00010413" ixy="-0.00000267" ixz="0.00000165" iyy="0.00255502" iyz="0.00000000" izz="0.00251726" />
            </inertial>
        </link>
        <!-- right knee pitch -->
        <joint name="r_knee_pitch_joint" type="revolute">
            <axis xyz="0 0 1" />
            <origin xyz="0.3 0 0" rpy="0 0 0"/>
            <parent link="r_hip_pitch_link"/>
            <child link="r_knee_pitch_link"/>
            <limit effort="10" lower="${-pi*0.9}" upper="${pi*0.9}" velocity="5.6548668"/>
            <dynamics damping="0.1" friction="0.0"/>
        </joint>
        <xacro:insert_transmission name="r_knee_pitch_joint"/>
        <link name="r_knee_pitch_link">
            <collision>
                <geometry>
                    <mesh filename="package://uthai_description/meshes/r_knee_pitch.STL"/>
                </geometry>
            </collision>
            <visual>
                <geometry>
                    <mesh filename="package://uthai_description/meshes/r_knee_pitch.STL"/>
                </geometry>
                <material name="grey"/>
            </visual>
            <inertial>
                <origin xyz="0.16353031 0.00000000 0.00023618"/>
                <mass value="0.13584790"/>
                <inertia ixx="0.00005765" ixy="0.00000000" ixz="0.00000009" iyy="0.00126779" iyz="0.00000000" izz="0.00124133" />
            </inertial>
        </link>
        <!-- right ankle pitch -->
        <joint name="r_ankle_pitch_joint" type="revolute">
            <axis xyz="0 0 1" />
            <origin xyz="0.315 0 0" rpy="0 0 0"/>
            <parent link="r_knee_pitch_link"/>
            <child link="r_ankle_pitch_link"/>
            <limit effort="10" lower="${-pi*0.9}" upper="${pi*0.9}" velocity="5.6548668"/>
            <dynamics damping="0.1" friction="0.0"/>
        </joint>
        <xacro:insert_transmission name="r_ankle_pitch_joint"/>
        <link name="r_ankle_pitch_link">
            <collision>
                <geometry>
                    <mesh filename="package://uthai_description/meshes/r_ankle_pitch.STL"/>
                </geometry>
            </collision>
            <visual>
                <geometry>
                    <mesh filename="package://uthai_description/meshes/r_ankle_pitch.STL"/>
                </geometry>
                <material name="grey"/>
            </visual>
            <inertial>
                <origin xyz="-0.01513929 0.02075769 0.00000789"/>
                <mass value="0.34200000"/>
                <inertia ixx="0.00027354" ixy="-0.00000709" ixz="-0.00000086" iyy="0.00014799" iyz="-0.00000008" izz="0.00032736" />
            </inertial>
        </link>
        <!-- right ankle roll -->
        <joint name="r_ankle_roll_joint" type="revolute">
            <axis xyz="0 0 1" />
            <origin xyz="0 0 0" rpy="${pi/2} 0 0"/>
            <parent link="r_ankle_pitch_link"/>
            <child link="r_ankle_roll_link"/>
            <limit effort="10" lower="${-pi*0.9}" upper="${pi*0.9}" velocity="5.6548668"/>
            <dynamics damping="0.1" friction="0.0"/>
        </joint>
        <xacro:insert_transmission name="r_ankle_roll_joint"/>
        <link name="r_ankle_roll_link">
            <collision>
                <geometry>
                    <mesh filename="package://uthai_description/meshes/r_ankle_roll.STL"/>
                </geometry>
            </collision>
            <visual>
                <geometry>
                    <mesh filename="package://uthai_description/meshes/r_ankle_roll.STL"/>
                </geometry>
                <material name="grey"/>
            </visual>
            <inertial>
                <origin xyz="0.03576926 -0.08779574 -0.00045842"/>
                <mass value="0.10500000"/>
                <inertia ixx="0.00123572" ixy="0.00000500" ixz="0.00000812" iyy="0.00031773" iyz="0.00000828" izz="0.00094763" />
            </inertial>
        </link>
    </xacro:macro>
</robot>